<?xml version="1.0" ?>
<!-- =================================================================================== -->
<!-- |    This document was autogenerated by xacro from warehouse_robots.urdf.xacro    | -->
<!-- |    EDITING THIS FILE BY HAND IS NOT RECOMMENDED                                 | -->
<!-- =================================================================================== -->
<robot name="warehouse_robots">
  <!-- Default material -->
  <material name="default_color">
    <color rgba="0.62745 0.62745 0.62745 1"/>
  </material>
  <!-- ===========================
       Base link
  ============================ -->
  <link name="base_link">
    <inertial>
      <origin rpy="0 0 0" xyz="0 0 0"/>
      <!-- <origin xyz="${-0.027013*S} ${-3.2999E-08*S} ${0.01722*S}" rpy="0 0 0"/> -->
      <!-- origin mass and inertia -->
      <!-- <mass value="3.777"/> -->
      <!-- <inertia ixx="0.011028" ixy="1.8783E-09" ixz="0.0017425"
               iyy="0.024419" iyz="-1.4644E-08" izz="0.03312"/> -->
      <!-- mass and inertia after scaling up -->
      <mass value="241.728"/>
      <inertia ixx="11.292672" ixy="1.923E-06" ixz="1.7664" iyy="25.005056" iyz="-1.500E-05" izz="33.91488"/>
    </inertial>
    <visual>
      <origin rpy="0 0 0" xyz="0 0 0"/>
      <geometry>
        <mesh filename="package://warehouse_robots/meshes/base_link.STL" scale="4.0 4.0 4.0"/>
      </geometry>
      <material name="default_color"/>
    </visual>
    <collision>
      <origin rpy="0 0 0" xyz="0 0 0"/>
      <geometry>
        <mesh filename="package://warehouse_robots/meshes/base_link.STL" scale="4.0 4.0 4.0"/>
      </geometry>
    </collision>
  </link>
  <link name="RB_wheel">
    <inertial>
      <origin rpy="0 0 0" xyz="0.0 0.0 -0.0300016"/>
      <mass value="0.082383"/>
      <inertia ixx="5.899E-05" ixy="0" ixz="0" iyy="5.899E-05" iyz="0" izz="0.0001153"/>
    </inertial>
    <visual>
      <origin rpy="0 0 0" xyz="0 0 0"/>
      <geometry>
        <mesh filename="package://warehouse_robots/meshes/RB_wheel.STL" scale="4.0 4.0 4.0"/>
      </geometry>
      <material name="default_color"/>
    </visual>
    <collision>
      <origin rpy="0 0 0" xyz="0 0 0"/>
      <geometry>
        <mesh filename="package://warehouse_robots/meshes/RB_wheel.STL" scale="4.0 4.0 4.0"/>
      </geometry>
    </collision>
  </link>
  <joint name="RB_wheel_joint" type="continuous">
    <origin rpy="1.5708 0 0" xyz="-0.43172 -0.494 -0.156"/>
    <parent link="base_link"/>
    <child link="RB_wheel"/>
    <axis xyz="0 0 -1"/>
    <limit effort="10" velocity="10"/>
    <dynamics damping="0.1" friction="0.1"/>
  </joint>
  <link name="RF_wheel">
    <inertial>
      <origin rpy="0 0 0" xyz="0.0 0.0 -0.0300016"/>
      <mass value="0.082383"/>
      <inertia ixx="5.899E-05" ixy="0" ixz="0" iyy="5.899E-05" iyz="0" izz="0.0001153"/>
    </inertial>
    <visual>
      <origin rpy="0 0 0" xyz="0 0 0"/>
      <geometry>
        <mesh filename="package://warehouse_robots/meshes/RF_wheel.STL" scale="4.0 4.0 4.0"/>
      </geometry>
      <material name="default_color"/>
    </visual>
    <collision>
      <origin rpy="0 0 0" xyz="0 0 0"/>
      <geometry>
        <mesh filename="package://warehouse_robots/meshes/RF_wheel.STL" scale="4.0 4.0 4.0"/>
      </geometry>
    </collision>
  </link>
  <joint name="RF_wheel_joint" type="continuous">
    <origin rpy="1.5708 0 0" xyz="0.48828 -0.494 -0.156"/>
    <parent link="base_link"/>
    <child link="RF_wheel"/>
    <axis xyz="0 0 -1"/>
    <limit effort="10" velocity="10"/>
    <dynamics damping="0.1" friction="0.1"/>
  </joint>
  <link name="LB_wheel">
    <inertial>
      <origin rpy="0 0 0" xyz="0.0 0.0 0.0299984"/>
      <mass value="0.082383"/>
      <inertia ixx="5.899E-05" ixy="0" ixz="0" iyy="5.899E-05" iyz="0" izz="0.0001153"/>
    </inertial>
    <visual>
      <origin rpy="0 0 0" xyz="0 0 0"/>
      <geometry>
        <mesh filename="package://warehouse_robots/meshes/LB_wheel.STL" scale="4.0 4.0 4.0"/>
      </geometry>
      <material name="default_color"/>
    </visual>
    <collision>
      <origin rpy="0 0 0" xyz="0 0 0"/>
      <geometry>
        <mesh filename="package://warehouse_robots/meshes/LB_wheel.STL" scale="4.0 4.0 4.0"/>
      </geometry>
    </collision>
  </link>
  <joint name="LB_wheel_joint" type="continuous">
    <origin rpy="1.5708 0 0" xyz="-0.43172 0.494 -0.156"/>
    <parent link="base_link"/>
    <child link="LB_wheel"/>
    <axis xyz="0 0 1"/>
    <limit effort="10" velocity="10"/>
    <dynamics damping="0.1" friction="0.1"/>
  </joint>
  <link name="LF_wheel">
    <inertial>
      <origin rpy="0 0 0" xyz="0.0 0.0 0.0299984"/>
      <mass value="0.082383"/>
      <inertia ixx="5.899E-05" ixy="0" ixz="0" iyy="5.899E-05" iyz="0" izz="0.0001153"/>
    </inertial>
    <visual>
      <origin rpy="0 0 0" xyz="0 0 0"/>
      <geometry>
        <mesh filename="package://warehouse_robots/meshes/LF_wheel.STL" scale="4.0 4.0 4.0"/>
      </geometry>
      <material name="default_color"/>
    </visual>
    <collision>
      <origin rpy="0 0 0" xyz="0 0 0"/>
      <geometry>
        <mesh filename="package://warehouse_robots/meshes/LF_wheel.STL" scale="4.0 4.0 4.0"/>
      </geometry>
    </collision>
  </link>
  <joint name="LF_wheel_joint" type="continuous">
    <origin rpy="1.5708 0 0" xyz="0.48828 0.494 -0.156"/>
    <parent link="base_link"/>
    <child link="LF_wheel"/>
    <axis xyz="0 0 1"/>
    <limit effort="10" velocity="10"/>
    <dynamics damping="0.1" friction="0.1"/>
  </joint>
  <!-- Diff Drive Plugin -->
  <plugin filename="libignition-gazebo-diff-drive-system.so" name="ignition::gazebo::systems::DiffDrive">
    <left_joint>LF_wheel_joint</left_joint>
    <left_joint>LB_wheel_joint</left_joint>
    <right_joint>RF_wheel_joint</right_joint>
    <right_joint>RB_wheel_joint</right_joint>
    <wheel_separation>0.988</wheel_separation>
    <wheel_radius>0.2</wheel_radius>
    <!-- Control topic -->
    <topic>cmd_vel</topic>
  </plugin>
</robot>
